2018-05-05 23:30:11,289 INFO: Microblog startup [in /Users/jiahuiwu/Desktop/microblog1/app/__init__.py:57]
2018-05-05 23:31:01,733 INFO: Microblog startup [in /Users/jiahuiwu/Desktop/microblog1/app/__init__.py:57]
2018-05-05 23:31:13,027 INFO: Microblog startup [in /Users/jiahuiwu/Desktop/microblog1/app/__init__.py:57]
2018-05-05 23:33:13,251 INFO: Microblog startup [in /Users/jiahuiwu/Desktop/microblog1/app/__init__.py:57]
2018-05-05 23:33:13,988 ERROR: Exception on /user/Jenny [GET] [in /Users/jiahuiwu/anaconda/lib/python3.6/site-packages/flask/app.py:1761]
Traceback (most recent call last):
  File "/Users/jiahuiwu/anaconda/lib/python3.6/site-packages/flask/app.py", line 2292, in wsgi_app
    response = self.full_dispatch_request()
  File "/Users/jiahuiwu/anaconda/lib/python3.6/site-packages/flask/app.py", line 1815, in full_dispatch_request
    rv = self.handle_user_exception(e)
  File "/Users/jiahuiwu/anaconda/lib/python3.6/site-packages/flask/app.py", line 1718, in handle_user_exception
    reraise(exc_type, exc_value, tb)
  File "/Users/jiahuiwu/anaconda/lib/python3.6/site-packages/flask/_compat.py", line 35, in reraise
    raise value
  File "/Users/jiahuiwu/anaconda/lib/python3.6/site-packages/flask/app.py", line 1813, in full_dispatch_request
    rv = self.dispatch_request()
  File "/Users/jiahuiwu/anaconda/lib/python3.6/site-packages/flask/app.py", line 1799, in dispatch_request
    return self.view_functions[rule.endpoint](**req.view_args)
  File "/Users/jiahuiwu/anaconda/lib/python3.6/site-packages/flask_login/utils.py", line 261, in decorated_view
    return func(*args, **kwargs)
  File "/Users/jiahuiwu/Desktop/microblog1/app/routes.py", line 165, in user
    temp=temp)
  File "/Users/jiahuiwu/anaconda/lib/python3.6/site-packages/flask/templating.py", line 135, in render_template
    context, ctx.app)
  File "/Users/jiahuiwu/anaconda/lib/python3.6/site-packages/flask/templating.py", line 117, in _render
    rv = template.render(context)
  File "/Users/jiahuiwu/anaconda/lib/python3.6/site-packages/jinja2/asyncsupport.py", line 76, in render
    return original_render(self, *args, **kwargs)
  File "/Users/jiahuiwu/anaconda/lib/python3.6/site-packages/jinja2/environment.py", line 1008, in render
    return self.environment.handle_exception(exc_info, True)
  File "/Users/jiahuiwu/anaconda/lib/python3.6/site-packages/jinja2/environment.py", line 780, in handle_exception
    reraise(exc_type, exc_value, tb)
  File "/Users/jiahuiwu/anaconda/lib/python3.6/site-packages/jinja2/_compat.py", line 37, in reraise
    raise value.with_traceback(tb)
  File "/Users/jiahuiwu/Desktop/microblog1/app/templates/user.html", line 1, in top-level template code
    {% extends "base.html" %}
  File "/Users/jiahuiwu/Desktop/microblog1/app/templates/base.html", line 1, in top-level template code
    {% extends 'bootstrap/base.html' %}
  File "/Users/jiahuiwu/anaconda/lib/python3.6/site-packages/flask_bootstrap/templates/bootstrap/base.html", line 1, in top-level template code
    {% block doc -%}
  File "/Users/jiahuiwu/anaconda/lib/python3.6/site-packages/flask_bootstrap/templates/bootstrap/base.html", line 4, in block "doc"
    {%- block html %}
  File "/Users/jiahuiwu/anaconda/lib/python3.6/site-packages/flask_bootstrap/templates/bootstrap/base.html", line 20, in block "html"
    {% block body -%}
  File "/Users/jiahuiwu/anaconda/lib/python3.6/site-packages/flask_bootstrap/templates/bootstrap/base.html", line 23, in block "body"
    {% block content -%}
  File "/Users/jiahuiwu/Desktop/microblog1/app/templates/base.html", line 48, in block "content"
    {% block app_content %}{% endblock %}
  File "/Users/jiahuiwu/Desktop/microblog1/app/templates/user.html", line 8, in block "app_content"
    <p><a href="{{ url_for('user.avatar(256)') }}">{{ _('Show avatar photo') }}</a></p>
  File "/Users/jiahuiwu/anaconda/lib/python3.6/site-packages/flask/helpers.py", line 356, in url_for
    return appctx.app.handle_url_build_error(error, endpoint, values)
  File "/Users/jiahuiwu/anaconda/lib/python3.6/site-packages/flask/app.py", line 2061, in handle_url_build_error
    reraise(exc_type, exc_value, tb)
  File "/Users/jiahuiwu/anaconda/lib/python3.6/site-packages/flask/_compat.py", line 35, in reraise
    raise value
  File "/Users/jiahuiwu/anaconda/lib/python3.6/site-packages/flask/helpers.py", line 345, in url_for
    force_external=external)
  File "/Users/jiahuiwu/anaconda/lib/python3.6/site-packages/werkzeug/routing.py", line 1776, in build
    raise BuildError(endpoint, values, method, self)
werkzeug.routing.BuildError: Could not build url for endpoint 'user.avatar(256)'. Did you mean 'user' instead?
2018-05-05 23:33:34,666 INFO: Microblog startup [in /Users/jiahuiwu/Desktop/microblog1/app/__init__.py:57]
2018-05-05 23:33:37,122 ERROR: Exception on /user/Jenny [GET] [in /Users/jiahuiwu/anaconda/lib/python3.6/site-packages/flask/app.py:1761]
Traceback (most recent call last):
  File "/Users/jiahuiwu/anaconda/lib/python3.6/site-packages/flask/app.py", line 2292, in wsgi_app
    response = self.full_dispatch_request()
  File "/Users/jiahuiwu/anaconda/lib/python3.6/site-packages/flask/app.py", line 1815, in full_dispatch_request
    rv = self.handle_user_exception(e)
  File "/Users/jiahuiwu/anaconda/lib/python3.6/site-packages/flask/app.py", line 1718, in handle_user_exception
    reraise(exc_type, exc_value, tb)
  File "/Users/jiahuiwu/anaconda/lib/python3.6/site-packages/flask/_compat.py", line 35, in reraise
    raise value
  File "/Users/jiahuiwu/anaconda/lib/python3.6/site-packages/flask/app.py", line 1813, in full_dispatch_request
    rv = self.dispatch_request()
  File "/Users/jiahuiwu/anaconda/lib/python3.6/site-packages/flask/app.py", line 1799, in dispatch_request
    return self.view_functions[rule.endpoint](**req.view_args)
  File "/Users/jiahuiwu/anaconda/lib/python3.6/site-packages/flask_login/utils.py", line 261, in decorated_view
    return func(*args, **kwargs)
  File "/Users/jiahuiwu/Desktop/microblog1/app/routes.py", line 165, in user
    temp=temp)
  File "/Users/jiahuiwu/anaconda/lib/python3.6/site-packages/flask/templating.py", line 135, in render_template
    context, ctx.app)
  File "/Users/jiahuiwu/anaconda/lib/python3.6/site-packages/flask/templating.py", line 117, in _render
    rv = template.render(context)
  File "/Users/jiahuiwu/anaconda/lib/python3.6/site-packages/jinja2/asyncsupport.py", line 76, in render
    return original_render(self, *args, **kwargs)
  File "/Users/jiahuiwu/anaconda/lib/python3.6/site-packages/jinja2/environment.py", line 1008, in render
    return self.environment.handle_exception(exc_info, True)
  File "/Users/jiahuiwu/anaconda/lib/python3.6/site-packages/jinja2/environment.py", line 780, in handle_exception
    reraise(exc_type, exc_value, tb)
  File "/Users/jiahuiwu/anaconda/lib/python3.6/site-packages/jinja2/_compat.py", line 37, in reraise
    raise value.with_traceback(tb)
  File "/Users/jiahuiwu/Desktop/microblog1/app/templates/user.html", line 1, in top-level template code
    {% extends "base.html" %}
  File "/Users/jiahuiwu/Desktop/microblog1/app/templates/base.html", line 1, in top-level template code
    {% extends 'bootstrap/base.html' %}
  File "/Users/jiahuiwu/anaconda/lib/python3.6/site-packages/flask_bootstrap/templates/bootstrap/base.html", line 1, in top-level template code
    {% block doc -%}
  File "/Users/jiahuiwu/anaconda/lib/python3.6/site-packages/flask_bootstrap/templates/bootstrap/base.html", line 4, in block "doc"
    {%- block html %}
  File "/Users/jiahuiwu/anaconda/lib/python3.6/site-packages/flask_bootstrap/templates/bootstrap/base.html", line 20, in block "html"
    {% block body -%}
  File "/Users/jiahuiwu/anaconda/lib/python3.6/site-packages/flask_bootstrap/templates/bootstrap/base.html", line 23, in block "body"
    {% block content -%}
  File "/Users/jiahuiwu/Desktop/microblog1/app/templates/base.html", line 48, in block "content"
    {% block app_content %}{% endblock %}
  File "/Users/jiahuiwu/Desktop/microblog1/app/templates/user.html", line 8, in block "app_content"
    <p><a href="{{ url_for('<img src="{{ user.avatar(256) }}">') }}">{{ _('Show avatar photo') }}</a></p>
  File "/Users/jiahuiwu/anaconda/lib/python3.6/site-packages/flask/helpers.py", line 356, in url_for
    return appctx.app.handle_url_build_error(error, endpoint, values)
  File "/Users/jiahuiwu/anaconda/lib/python3.6/site-packages/flask/app.py", line 2061, in handle_url_build_error
    reraise(exc_type, exc_value, tb)
  File "/Users/jiahuiwu/anaconda/lib/python3.6/site-packages/flask/_compat.py", line 35, in reraise
    raise value
  File "/Users/jiahuiwu/anaconda/lib/python3.6/site-packages/flask/helpers.py", line 345, in url_for
    force_external=external)
  File "/Users/jiahuiwu/anaconda/lib/python3.6/site-packages/werkzeug/routing.py", line 1776, in build
    raise BuildError(endpoint, values, method, self)
werkzeug.routing.BuildError: Could not build url for endpoint '<img src="{{ user.avatar(256) }}">'. Did you mean 'reset_password' instead?
