2018-05-05 23:00:09,057 ERROR: Exception on /edit_profile [GET] [in /Users/jiahuiwu/anaconda/lib/python3.6/site-packages/flask/app.py:1761]
Traceback (most recent call last):
  File "/Users/jiahuiwu/anaconda/lib/python3.6/site-packages/flask/app.py", line 2292, in wsgi_app
    response = self.full_dispatch_request()
  File "/Users/jiahuiwu/anaconda/lib/python3.6/site-packages/flask/app.py", line 1815, in full_dispatch_request
    rv = self.handle_user_exception(e)
  File "/Users/jiahuiwu/anaconda/lib/python3.6/site-packages/flask/app.py", line 1718, in handle_user_exception
    reraise(exc_type, exc_value, tb)
  File "/Users/jiahuiwu/anaconda/lib/python3.6/site-packages/flask/_compat.py", line 35, in reraise
    raise value
  File "/Users/jiahuiwu/anaconda/lib/python3.6/site-packages/flask/app.py", line 1813, in full_dispatch_request
    rv = self.dispatch_request()
  File "/Users/jiahuiwu/anaconda/lib/python3.6/site-packages/flask/app.py", line 1799, in dispatch_request
    return self.view_functions[rule.endpoint](**req.view_args)
  File "/Users/jiahuiwu/anaconda/lib/python3.6/site-packages/flask_login/utils.py", line 261, in decorated_view
    return func(*args, **kwargs)
  File "/Users/jiahuiwu/Desktop/microblog1/app/routes.py", line 185, in edit_profile
    form=form)
  File "/Users/jiahuiwu/anaconda/lib/python3.6/site-packages/flask/templating.py", line 135, in render_template
    context, ctx.app)
  File "/Users/jiahuiwu/anaconda/lib/python3.6/site-packages/flask/templating.py", line 117, in _render
    rv = template.render(context)
  File "/Users/jiahuiwu/anaconda/lib/python3.6/site-packages/jinja2/asyncsupport.py", line 76, in render
    return original_render(self, *args, **kwargs)
  File "/Users/jiahuiwu/anaconda/lib/python3.6/site-packages/jinja2/environment.py", line 1008, in render
    return self.environment.handle_exception(exc_info, True)
  File "/Users/jiahuiwu/anaconda/lib/python3.6/site-packages/jinja2/environment.py", line 780, in handle_exception
    reraise(exc_type, exc_value, tb)
  File "/Users/jiahuiwu/anaconda/lib/python3.6/site-packages/jinja2/_compat.py", line 37, in reraise
    raise value.with_traceback(tb)
  File "/Users/jiahuiwu/Desktop/microblog1/app/templates/edit_profile.html", line 2, in top-level template code
    {% import 'bootstrap/wtf.html' as wtf %}
  File "/Users/jiahuiwu/Desktop/microblog1/app/templates/base.html", line 1, in top-level template code
    {% extends 'bootstrap/base.html' %}
  File "/Users/jiahuiwu/anaconda/lib/python3.6/site-packages/flask_bootstrap/templates/bootstrap/base.html", line 1, in top-level template code
    {% block doc -%}
  File "/Users/jiahuiwu/anaconda/lib/python3.6/site-packages/flask_bootstrap/templates/bootstrap/base.html", line 4, in block "doc"
    {%- block html %}
  File "/Users/jiahuiwu/anaconda/lib/python3.6/site-packages/flask_bootstrap/templates/bootstrap/base.html", line 20, in block "html"
    {% block body -%}
  File "/Users/jiahuiwu/anaconda/lib/python3.6/site-packages/flask_bootstrap/templates/bootstrap/base.html", line 23, in block "body"
    {% block content -%}
  File "/Users/jiahuiwu/Desktop/microblog1/app/templates/base.html", line 48, in block "content"
    {% block app_content %}{% endblock %}
  File "/Users/jiahuiwu/Desktop/microblog1/app/templates/edit_profile.html", line 11, in block "app_content"
    {{ render_field(form.username, placeholder="Enter Recipe Title") }}
jinja2.exceptions.UndefinedError: 'render_field' is undefined
2018-05-05 23:00:34,071 INFO: Microblog startup [in /Users/jiahuiwu/Desktop/microblog1/app/__init__.py:57]
2018-05-05 23:00:35,673 ERROR: Exception on /edit_profile [GET] [in /Users/jiahuiwu/anaconda/lib/python3.6/site-packages/flask/app.py:1761]
Traceback (most recent call last):
  File "/Users/jiahuiwu/anaconda/lib/python3.6/site-packages/flask/app.py", line 2292, in wsgi_app
    response = self.full_dispatch_request()
  File "/Users/jiahuiwu/anaconda/lib/python3.6/site-packages/flask/app.py", line 1815, in full_dispatch_request
    rv = self.handle_user_exception(e)
  File "/Users/jiahuiwu/anaconda/lib/python3.6/site-packages/flask/app.py", line 1718, in handle_user_exception
    reraise(exc_type, exc_value, tb)
  File "/Users/jiahuiwu/anaconda/lib/python3.6/site-packages/flask/_compat.py", line 35, in reraise
    raise value
  File "/Users/jiahuiwu/anaconda/lib/python3.6/site-packages/flask/app.py", line 1813, in full_dispatch_request
    rv = self.dispatch_request()
  File "/Users/jiahuiwu/anaconda/lib/python3.6/site-packages/flask/app.py", line 1799, in dispatch_request
    return self.view_functions[rule.endpoint](**req.view_args)
  File "/Users/jiahuiwu/anaconda/lib/python3.6/site-packages/flask_login/utils.py", line 261, in decorated_view
    return func(*args, **kwargs)
  File "/Users/jiahuiwu/Desktop/microblog1/app/routes.py", line 185, in edit_profile
    form=form)
  File "/Users/jiahuiwu/anaconda/lib/python3.6/site-packages/flask/templating.py", line 135, in render_template
    context, ctx.app)
  File "/Users/jiahuiwu/anaconda/lib/python3.6/site-packages/flask/templating.py", line 117, in _render
    rv = template.render(context)
  File "/Users/jiahuiwu/anaconda/lib/python3.6/site-packages/jinja2/asyncsupport.py", line 76, in render
    return original_render(self, *args, **kwargs)
  File "/Users/jiahuiwu/anaconda/lib/python3.6/site-packages/jinja2/environment.py", line 1008, in render
    return self.environment.handle_exception(exc_info, True)
  File "/Users/jiahuiwu/anaconda/lib/python3.6/site-packages/jinja2/environment.py", line 780, in handle_exception
    reraise(exc_type, exc_value, tb)
  File "/Users/jiahuiwu/anaconda/lib/python3.6/site-packages/jinja2/_compat.py", line 37, in reraise
    raise value.with_traceback(tb)
  File "/Users/jiahuiwu/Desktop/microblog1/app/templates/edit_profile.html", line 3, in top-level template code
    {% from "_form_macros.html" import render_field %}
  File "/Users/jiahuiwu/anaconda/lib/python3.6/site-packages/flask/templating.py", line 58, in get_source
    return self._get_source_fast(environment, template)
  File "/Users/jiahuiwu/anaconda/lib/python3.6/site-packages/flask/templating.py", line 86, in _get_source_fast
    raise TemplateNotFound(template)
jinja2.exceptions.TemplateNotFound: _form_macros.html
2018-05-05 23:02:26,859 INFO: Microblog startup [in /Users/jiahuiwu/Desktop/microblog1/app/__init__.py:57]
2018-05-05 23:02:41,792 ERROR: Exception on /edit_profile [POST] [in /Users/jiahuiwu/anaconda/lib/python3.6/site-packages/flask/app.py:1761]
Traceback (most recent call last):
  File "/Users/jiahuiwu/anaconda/lib/python3.6/site-packages/flask/app.py", line 2292, in wsgi_app
    response = self.full_dispatch_request()
  File "/Users/jiahuiwu/anaconda/lib/python3.6/site-packages/flask/app.py", line 1815, in full_dispatch_request
    rv = self.handle_user_exception(e)
  File "/Users/jiahuiwu/anaconda/lib/python3.6/site-packages/flask/app.py", line 1718, in handle_user_exception
    reraise(exc_type, exc_value, tb)
  File "/Users/jiahuiwu/anaconda/lib/python3.6/site-packages/flask/_compat.py", line 35, in reraise
    raise value
  File "/Users/jiahuiwu/anaconda/lib/python3.6/site-packages/flask/app.py", line 1813, in full_dispatch_request
    rv = self.dispatch_request()
  File "/Users/jiahuiwu/anaconda/lib/python3.6/site-packages/flask/app.py", line 1799, in dispatch_request
    return self.view_functions[rule.endpoint](**req.view_args)
  File "/Users/jiahuiwu/anaconda/lib/python3.6/site-packages/flask_login/utils.py", line 261, in decorated_view
    return func(*args, **kwargs)
  File "/Users/jiahuiwu/Desktop/microblog1/app/routes.py", line 175, in edit_profile
    filename = images.save(request.files['image'])
  File "/Users/jiahuiwu/anaconda/lib/python3.6/site-packages/flask_uploads.py", line 422, in save
    os.makedirs(target_folder)
  File "/Users/jiahuiwu/anaconda/lib/python3.6/os.py", line 210, in makedirs
    makedirs(head, mode, exist_ok)
  File "/Users/jiahuiwu/anaconda/lib/python3.6/os.py", line 210, in makedirs
    makedirs(head, mode, exist_ok)
  File "/Users/jiahuiwu/anaconda/lib/python3.6/os.py", line 220, in makedirs
    mkdir(name, mode)
PermissionError: [Errno 13] Permission denied: '/app'
2018-05-05 23:04:11,839 INFO: Microblog startup [in /Users/jiahuiwu/Desktop/microblog1/app/__init__.py:57]
